print chr(1024)


'''
$ python exceptions_ValueError.py

Traceback (most recent call last):
  File "exceptions_ValueError.py", line 12, in <module>
    print chr(1024)
ValueError: chr() arg not in range(256)
'''